Workbook

Sheet Torsty-MLST
A1: sampleid | B1: species | C1: subspecies | D1: ST_ariba-as | E1: TP0136_ariba-as | F1: TP0548_ariba-as | G1: TP0705_ariba-as | H1: ST_spades | I1: TP0136_spades | J1: TP0548_spades | K1: TP0705_spades | L1: same_ST | M1: same_136 | N1: same_548 | O1: same_705 | P1: TP0136_consensus | Q1: TP0548_consensus | R1: TP0705_consensus | S1: ST_Consensus | T1: pubmlst_ST | U1: ST_Method_Consensus
A2: 15169_6#52.Treponema.ds2500000-reads | B2: tpallidum | C2: TPA | D2: - | E2: 10? | F2: 14 | G2: 10 | H2: 20 | I2: 10 | J2: 14 | K2: 10 | L2: different | M2: different | N2: same | O2: same | P2: 10 | Q2: 14 | R2: 10 | S2: 20 | T2: - | U2: 20
A3: 15169_6#53.Treponema.ds2352679-reads | B3: tpallidum | C3: TEN | D3: - | E3: 11? | F3: 50? | G3: 10 | H3: - | I3: 17? | J3: 50? | K3: 10 | L3: same | M3: different | N3: same | O3: same | P3: - | Q3: 50? | R3: 10 | S3: - | T3: - | U3: -
A4: 15169_6#54.Treponema.ds2500000-reads | B4: tpallidum | C4: TPA | D4: - | E4: 10? | F4: 14 | G4: 10 | H4: 20 | I4: 10 | J4: 14 | K4: 10 | L4: different | M4: different | N4: same | O4: same | P4: 10 | Q4: 14 | R4: 10 | S4: 20 | T4: - | U4: 20
A5: 15169_6#56.Treponema.ds2500000-reads | B5: tpallidum | C5: TPA | D5: - | E5: 10? | F5: 14 | G5: 10 | H5: 20 | I5: 10 | J5: 14 | K5: 10 | L5: different | M5: different | N5: same | O5: same | P5: 10 | Q5: 14 | R5: 10 | S5: 20 | T5: - | U5: 20
A6: 15169_6#60.Treponema.ds2500000-reads | B6: tpallidum | C6: TPA | D6: - | E6: 10? | F6: 14 | G6: 10 | H6: 20 | I6: 10 | J6: 14 | K6: 10 | L6: different | M6: different | N6: same | O6: same | P6: 10 | Q6: 14 | R6: 10 | S6: 20 | T6: - | U6: 20
A7: 15169_6#65.Treponema.ds2500000-reads | B7: tpallidum | C7: TPA | D7: - | E7: 6 | F7: 13 | G7: 10 | H7: 21 | I7: 1 | J7: 13 | K7: 10 | L7: different | M7: different | N7: same | O7: same | P7: - | Q7: 13 | R7: 10 | S7: 21 | T7: 21 | U7: 21
A8: 15169_7#74.Treponema.ds2500000-reads | B8: tpallidum | C8: TPA | D8: - | E8: 11? | F8: 15 | G8: 10 | H8: 23 | I8: 12 | J8: 15 | K8: 10 | L8: different | M8: different | N8: same | O8: same | P8: 12 | Q8: 15 | R8: 10 | S8: 23 | T8: - | U8: 23
A9: 19444_8#14.Treponema.ds2033782-reads | B9: tpallidum | C9: TPE | D9: - | E9: 11? | F9: 15? | G9: 10 | H9: - | I9: 11? | J9: 15? | K9: 10 | L9: same | M9: same | N9: same | O9: same | P9: 11? | Q9: 15? | R9: 10 | S9: - | T9: - | U9: -
A10: 19444_8#15.Treponema.ds1410649-reads | B10: tpallidum | C10: TPE | D10: - | E10: 11? | F10: 15? | G10: 10 | H10: - | I10: 11? | J10: 15? | K10: 10 | L10: same | M10: same | N10: same | O10: same | P10: 11? | Q10: 15? | R10: 10 | S10: - | T10: - | U10: -
A11: 19444_8#2.Treponema.ds2500000-reads | B11: tpallidum | C11: TPE | D11: - | E11: 11? | F11: 15? | G11: 10 | H11: - | I11: 11? | J11: 15? | K11: 10 | L11: same | M11: same | N11: same | O11: same | P11: 11? | Q11: 15? | R11: 10 | S11: - | T11: - | U11: -
A12: 19444_8#6.Treponema.ds996438-reads | B12: - | C12: TPE | D12: - | H12: - | I12: 11? | J12: 15? | K12: 10 | L12: same | M12: different | N12: different | O12: different | P12: - | Q12: - | R12: 10 | S12: - | T12: - | U12: -
A13: 19444_8#9.Treponema.ds1440088-reads | B13: tpallidum | C13: TPE | D13: - | E13: 11? | F13: 15? | G13: 10 | H13: - | I13: 11? | J13: 15? | K13: 10 | L13: same | M13: same | N13: same | O13: same | P13: 11? | Q13: 15? | R13: 10 | S13: - | T13: - | U13: -
A14: 22931_6#11.Treponema.ds2500000-reads | B14: tpallidum | C14: TPA | D14: - | E14: 35? | F14: 1 | G14: 1 | H14: 2 | I14: 1 | J14: 1 | K14: 1 | L14: different | M14: different | N14: same | O14: same | P14: 1 | Q14: 1 | R14: 1 | S14: 2 | T14: - | U14: 2
A15: 22931_6#12.Treponema.ds778035-reads | B15: tpallidum | C15: TPA | D15: - | E15: 24? | F15: 2 | G15: 3 | H15: - | I15: 24? | J15: 2 | K15: 3 | L15: same | M15: same | N15: same | O15: same | P15: 24? | Q15: 2 | R15: 3 | S15: - | T15: - | U15: -
A16: 22931_6#13.Treponema.ds2422288-reads | B16: tpallidum | C16: TPA | D16: - | E16: 24? | F16: 2 | G16: 3 | H16: 6 | I16: 3 | J16: 2 | K16: 3 | L16: different | M16: different | N16: same | O16: same | P16: 3 | Q16: 2 | R16: 3 | S16: 6 | T16: - | U16: 6
A17: 22931_6#4.Treponema.ds2207961-reads | B17: tpallidum | C17: TPA | D17: - | E17: 6 | F17: 1 | G17: 1 | H17: 2 | I17: 1 | J17: 1 | K17: 1 | L17: different | M17: different | N17: same | O17: same | P17: - | Q17: 1 | R17: 1 | S17: - | T17: - | U17: -
A18: 22931_6#5.Treponema.ds2500000-reads | B18: tpallidum | C18: TPA | D18: - | E18: 21? | F18: 3 | G18: 1 | H18: 1 | I18: 1 | J18: 3 | K18: 1 | L18: different | M18: different | N18: same | O18: same | P18: 1 | Q18: 3 | R18: 1 | S18: 1 | T18: - | U18: 1
A19: 22931_6#6.Treponema.ds2500000-reads | B19: tpallidum | C19: TPA | D19: - | E19: 35? | F19: 3 | G19: 1 | H19: 1 | I19: 1 | J19: 3 | K19: 1 | L19: different | M19: different | N19: same | O19: same | P19: 1 | Q19: 3 | R19: 1 | S19: 1 | T19: - | U19: 1
A20: 22931_6#7.Treponema.ds726081-reads | B20: tpallidum | C20: TPA | D20: 72 | E20: 22 | F20: 3 | G20: 1 | H20: - | I20: 22? | J20: 3 | K20: 1 | L20: different | M20: different | N20: same | O20: same | P20: 22 | Q20: 3 | R20: 1 | S20: 72 | T20: - | U20: 72
A21: 22931_6#8.Treponema.ds1618428-reads | B21: tpallidum | C21: TPA | D21: 13 | E21: 6 | F21: 3 | G21: 1 | H21: 1 | I21: 1 | J21: 3 | K21: 1 | L21: different | M21: different | N21: same | O21: same | P21: - | Q21: 3 | R21: 1 | S21: conflict | T21: - | U21: conflict
A22: 22931_6#9.Treponema.ds2500000-reads | B22: tpallidum | C22: TPA | D22: - | E22: 24? | F22: 2 | G22: 3 | H22: 6 | I22: 3 | J22: 2 | K22: 3 | L22: different | M22: different | N22: same | O22: same | P22: 3 | Q22: 2 | R22: 3 | S22: 6 | T22: - | U22: 6
A23: 24141_3#11.Treponema.ds2500000-reads | B23: tpallidum | C23: TPA | D23: - | E23: 1 | F23: 1 | G23: 2 | H23: - | I23: 1 | J23: 1 | K23: 2 | L23: same | M23: same | N23: same | O23: same | P23: 1 | Q23: 1 | R23: 2 | S23: N1 | T23: - | U23: N1
A24: 24141_3#16.Treponema.ds2500000-reads | B24: tpallidum | C24: TPA | D24: 11 | E24: 1 | F24: 1 | G24: 3 | H24: 11 | I24: 1 | J24: 1 | K24: 3 | L24: same | M24: same | N24: same | O24: same | P24: 1 | Q24: 1 | R24: 3 | S24: 11 | T24: - | U24: 11
A25: 24141_3#17.Treponema.ds2500000-reads | B25: tpallidum | C25: TPA | D25: - | E25: 1? | F25: 3 | G25: 1 | H25: 1 | I25: 1 | J25: 3 | K25: 1 | L25: different | M25: different | N25: same | O25: same | P25: 1 | Q25: 3 | R25: 1 | S25: 1 | T25: - | U25: 1
A26: 24141_4#11.Treponema.ds2500000-reads | B26: tpallidum | C26: TPA | D26: - | E26: 1 | F26: ~1 | G26: 2 | H26: - | I26: 1 | J26: ~1 | K26: 2 | L26: same | M26: same | N26: same | O26: same | P26: 1 | Q26: ~1 | R26: 2 | S26: - | T26: - | U26: -
A27: 24141_4#12.Treponema.ds2500000-reads | B27: tpallidum | C27: TPA | D27: 11 | E27: 1 | F27: 1 | G27: 3 | H27: 11 | I27: 1 | J27: 1 | K27: 3 | L27: same | M27: same | N27: same | O27: same | P27: 1 | Q27: 1 | R27: 3 | S27: 11 | T27: - | U27: 11
A28: 24141_4#15.Treponema.ds2500000-reads | B28: tpallidum | C28: TPA | D28: 27 | E28: 1 | F28: 1 | G28: 9 | H28: 27 | I28: 1 | J28: 1 | K28: 9 | L28: same | M28: same | N28: same | O28: same | P28: 1 | Q28: 1 | R28: 9 | S28: 27 | T28: 27 | U28: 27
A29: 24141_4#18.Treponema.ds2500000-reads | B29: tpallidum | C29: TPA | D29: - | E29: 1 | F29: 1 | G29: 2 | H29: - | I29: 1 | J29: 1 | K29: 2 | L29: same | M29: same | N29: same | O29: same | P29: 1 | Q29: 1 | R29: 2 | S29: N1 | T29: - | U29: N1
A30: 24141_4#19.Treponema.ds2500000-reads | B30: tpallidum | C30: TPA | D30: 27 | E30: 1 | F30: 1 | G30: 9 | H30: 27 | I30: 1 | J30: 1 | K30: 9 | L30: same | M30: same | N30: same | O30: same | P30: 1 | Q30: 1 | R30: 9 | S30: 27 | T30: - | U30: 27
A31: 24141_4#6.Treponema.ds2500000-reads | B31: tpallidum | C31: TPA | D31: 11 | E31: 1 | F31: 1 | G31: 3 | H31: 11 | I31: 1 | J31: 1 | K31: 3 | L31: same | M31: same | N31: same | O31: same | P31: 1 | Q31: 1 | R31: 3 | S31: 11 | T31: - | U31: 11
A32: 24141_5#11.Treponema.ds2500000-reads | B32: tpallidum | C32: TPA | D32: 1 | E32: 1 | F32: 3 | G32: 1 | H32: 1 | I32: 1 | J32: 3 | K32: 1 | L32: same | M32: same | N32: same | O32: same | P32: 1 | Q32: 3 | R32: 1 | S32: 1 | T32: - | U32: 1
A33: 24141_5#12.Treponema.ds2500000-reads | B33: tpallidum | C33: TPA | D33: - | E33: 1 | F33: 1 | G33: 2 | H33: - | I33: 1 | J33: 1 | K33: 2 | L33: same | M33: same | N33: same | O33: same | P33: 1 | Q33: 1 | R33: 2 | S33: N1 | T33: - | U33: N1
A34: 24141_5#15.Treponema.ds2500000-reads | B34: tpallidum | C34: TPA | D34: 2 | E34: 1 | F34: 1 | G34: 1 | H34: 2 | I34: 1 | J34: 1 | K34: 1 | L34: same | M34: same | N34: same | O34: same | P34: 1 | Q34: 1 | R34: 1 | S34: 2 | T34: - | U34: 2
A35: 24141_5#16.Treponema.ds2500000-reads | B35: tpallidum | C35: TPA | D35: 2 | E35: 1 | F35: 1 | G35: 1 | H35: 2 | I35: 1 | J35: 1 | K35: 1 | L35: same | M35: same | N35: same | O35: same | P35: 1 | Q35: 1 | R35: 1 | S35: 2 | T35: - | U35: 2
A36: 24141_5#17.Treponema.ds2500000-reads | B36: tpallidum | C36: TPA | D36: 11 | E36: 1 | F36: 1 | G36: 3 | H36: 11 | I36: 1 | J36: 1 | K36: 3 | L36: same | M36: same | N36: same | O36: same | P36: 1 | Q36: 1 | R36: 3 | S36: 11 | T36: - | U36: 11
A37: 24141_5#18.Treponema.ds2471082-reads | B37: tpallidum | C37: TPA | D37: - | E37: 28 | F37: 7 | G37: 3 | H37: 26 | I37: 9 | J37: 7 | K37: 3 | L37: different | M37: different | N37: same | O37: same | P37: - | Q37: 7 | R37: 3 | S37: - | T37: 26 | U37: 26
A38: 24141_5#20.Treponema.ds2500000-reads | B38: tpallidum | C38: TPA | D38: - | E38: 1 | F38: 1 | G38: 2 | H38: - | I38: 1 | J38: 1 | K38: 2 | L38: same | M38: same | N38: same | O38: same | P38: 1 | Q38: 1 | R38: 2 | S38: N1 | T38: - | U38: N1
A39: 24141_5#4.Treponema.ds2500000-reads | B39: tpallidum | C39: TPA | D39: 27 | E39: 1 | F39: 1 | G39: 9 | H39: 27 | I39: 1 | J39: 1 | K39: 9 | L39: same | M39: same | N39: same | O39: same | P39: 1 | Q39: 1 | R39: 9 | S39: 27 | T39: - | U39: 27
A40: 24141_5#5.Treponema.ds2500000-reads | B40: tpallidum | C40: TPA | D40: 2 | E40: 1 | F40: 1 | G40: 1 | H40: 2 | I40: 1 | J40: 1 | K40: 1 | L40: same | M40: same | N40: same | O40: same | P40: 1 | Q40: 1 | R40: 1 | S40: 2 | T40: - | U40: 2
...

Sheet Export
A1: id | B1: isolate | C1: biosample_accession | D1: NCBI_assembly_accession | E1: run_accession | F1: curator | G1: TREP0136 | H1: TREP0548 | I1: TREP0705 | J1: TP0136 | K1: TP0548 | L1: TP0705 | M1: ST (MLST (Grillová)) | N1: clonal_complex (MLST (Grillová)) | O1: BACT000001 | P1: BACT000002 | Q1: BACT000003 | R1: BACT000004 | S1: BACT000005 | T1: BACT000006 | U1: BACT000007 | V1: BACT000008 | W1: BACT000009 | X1: BACT000010 | Y1: BACT000011 | Z1: BACT000012 | AA1: BACT000013 | AB1: BACT000014 | AC1: BACT000015 | AD1: BACT000016 | AE1: BACT000017 | AF1: BACT000018 | AG1: BACT000019 | AH1: BACT000020 | AI1: BACT000021 | AJ1: BACT000030 | AK1: BACT000031 | AL1: BACT000032 | AM1: BACT000033 | AN1: BACT000034 | AO1: BACT000035 | AP1: BACT000036 | AQ1: BACT000038 | AR1: BACT000039 | AS1: BACT000040 | AT1: BACT000042 | AU1: BACT000043 | AV1: BACT000044 | AW1: BACT000045 | AX1: BACT000046 | AY1: BACT000047 | AZ1: BACT000048 | BA1: BACT000049 | BB1: BACT000050 | BC1: BACT000051 | BD1: BACT000052 | BE1: BACT000053 | BF1: BACT000056 | BG1: BACT000057 | BH1: BACT000058 | BI1: BACT000059 | BJ1: BACT000060 | BK1: BACT000061 | BL1: BACT000062 | BM1: BACT000063 | BN1: BACT000064 | BO1: BACT000065 | BP1: rST (Ribosomal MLST) | BQ1: genus (Ribosomal MLST) | BR1: species (Ribosomal MLST) | BS1: subspecies (Ribosomal MLST) | BT1: lineage (Ribosomal MLST) | BU1: sublineage (Ribosomal MLST) | BV1: other_designation (Ribosomal MLST) | BW1: notes (Ribosomal MLST) | BX1: MPD_TP0136 | BY1: MPD_TP0326 | BZ1: MPD_TP0548 | CA1: MPD_TP0705 | CB1: MPD_TP0858 | CC1: MPD_TP0865 | CD1: MPD_TP1031 | CE1: ST (MLST (Pla-Díaz))
A2: 1 | B2: SHC_0 | F2: -1 | G2: 2 | H2: 2 | I2: 2 | J2: 1 | K2: 1 | L2: 8 | M2: 3 | N2: SS14-like | O2: 10110 | P2: 585 | Q2: 525 | R2: 552 | S2: 466 | T2: 420 | U2: 527 | V2: 462 | W2: 517 | X2: 455 | Y2: 474 | Z2: 496 | AA2: 482 | AB2: 434 | AC2: 469 | AD2: 497 | AE2: 427 | AF2: 416 | AG2: 440 | AH2: 407 | AI2: 360 | AJ2: 593 | AK2: 513 | AL2: 482 | AM2: 546 | AN2: 4257 | AO2: 519 | AP2: 478 | AQ2: 513 | AR2: 544 | AS2: 491 | AT2: 478 | AU2: 425 | AW2: 471 | AX2: 443 | AY2: 479 | AZ2: 498 | BA2: 512 | BB2: 457 | BC2: 494 | BD2: 422 | BE2: 493 | BF2: 488 | BG2: 470 | BH2: 4472 | BI2: 384 | BJ2: 431 | BK2: 458 | BL2: 429 | BM2: 430 | BN2: 400 | BO2: 390
A3: 2 | B3: SHD_R | F3: -1 | G3: 2 | H3: 2 | I3: 2 | J3: 1 | K3: 1 | L3: 8 | M3: 3 | N3: SS14-like | O3: 10110 | P3: 585 | Q3: 525 | R3: 552 | S3: 466 | T3: 420 | U3: 527 | V3: 462 | W3: 517 | X3: 455 | Y3: 474 | Z3: 496 | AA3: 482 | AB3: 434 | AC3: 469 | AD3: 497 | AE3: 427 | AF3: 416 | AG3: 440 | AH3: 407 | AI3: 360 | AJ3: 593 | AK3: 513 | AL3: 482 | AM3: 546 | AN3: 4257 | AO3: 519 | AP3: 478 | AQ3: 513 | AR3: 544 | AS3: 491 | AT3: 478 | AU3: 425 | AW3: 471 | AX3: 443 | AY3: 479 | AZ3: 498 | BA3: 512 | BB3: 457 | BC3: 494 | BD3: 422 | BE3: 493 | BF3: 488 | BG3: 470 | BH3: 4472 | BI3: 384 | BJ3: 431 | BK3: 458 | BL3: 429 | BM3: 430 | BN3: 400 | BO3: 390
A4: 3 | B4: SHE_V | F4: -1 | G4: 2 | H4: 2 | I4: 2 | J4: 1 | K4: 1 | L4: 8 | M4: 3 | N4: SS14-like | O4: 10110 | P4: 585 | Q4: 525 | R4: 552 | S4: 466 | T4: 420 | U4: 527 | V4: 462 | W4: 517 | X4: 455 | Y4: 474 | Z4: 496 | AA4: 482 | AB4: 434 | AC4: 469 | AD4: 497 | AE4: 427 | AF4: 416 | AG4: 440 | AH4: 407 | AI4: 360 | AJ4: 593 | AK4: 513 | AL4: 482 | AM4: 546 | AN4: 4257 | AO4: 519 | AP4: 478 | AQ4: 513 | AR4: 544 | AS4: 491 | AT4: 478 | AU4: 425 | AW4: 471 | AX4: 443 | AY4: 479 | AZ4: 498 | BA4: 512 | BB4: 457 | BC4: 494 | BD4: 422 | BE4: 493 | BF4: 488 | BG4: 470 | BH4: 4472 | BI4: 384 | BJ4: 431 | BK4: 458 | BL4: 429 | BM4: 430 | BN4: 400 | BO4: 390
A5: 4 | B5: SGF_12 | F5: -1 | G5: 2 | H5: 2 | I5: 2 | J5: 1 | K5: 1 | L5: 8 | M5: 3 | N5: SS14-like | O5: 10110 | P5: 585 | Q5: 525 | R5: 552 | S5: 466 | T5: 420 | U5: 527 | V5: 462 | W5: 517 | X5: 455 | Y5: 474 | Z5: 496 | AA5: 482 | AB5: 434 | AC5: 469 | AD5: 497 | AE5: 427 | AF5: 416 | AG5: 440 | AH5: 407 | AI5: 360 | AJ5: 593 | AK5: 513 | AL5: 482 | AM5: 546 | AN5: 4257 | AO5: 519 | AP5: 478 | AQ5: 513 | AR5: 544 | AS5: 491 | AT5: 478 | AU5: 425 | AV5: 434 | AW5: 471 | AX5: 443 | AY5: 479 | AZ5: 498 | BA5: 512 | BB5: 457 | BC5: 494 | BD5: 422 | BE5: 493 | BF5: 488 | BG5: 470 | BH5: 4472 | BI5: 384 | BJ5: 431 | BK5: 458 | BL5: 429 | BM5: 430 | BN5: 400 | BO5: 390 | BP5: 171492 | BQ5: Treponema | BR5: Treponema pallidum
A6: 5 | B6: B3 | F6: -1 | G6: 2 | H6: 2 | I6: 2 | J6: 1 | K6: 1 | L6: 8 | M6: 3 | N6: SS14-like | O6: 10110 | P6: 585 | Q6: 525 | R6: 552 | S6: 466 | T6: 420 | U6: 527 | V6: 462 | W6: 517 | X6: 455 | Y6: 474 | Z6: 496 | AA6: 482 | AB6: 434 | AC6: 469 | AD6: 497 | AE6: 427 | AF6: 416 | AG6: 440 | AH6: 407 | AI6: 360 | AJ6: 593 | AK6: 513 | AL6: 482 | AM6: 546 | AN6: 4257 | AO6: 519 | AP6: 478 | AQ6: 513 | AR6: 544 | AS6: 491 | AT6: 478 | AU6: 425 | AV6: 434 | AW6: 471 | AX6: 443 | AY6: 479 | AZ6: 498 | BA6: 512 | BB6: 457 | BC6: 494 | BD6: 422 | BE6: 493 | BF6: 488 | BG6: 470 | BH6: 4472 | BI6: 384 | BJ6: 431 | BK6: 458 | BL6: 429 | BM6: 430 | BN6: 400 | BO6: 390 | BP6: 171492 | BQ6: Treponema | BR6: Treponema pallidum
A7: 6 | B7: C3 | F7: -1 | G7: 2 | I7: 2 | J7: 1 | L7: 8 | O7: 10110 | P7: 585 | Q7: 525 | R7: 552 | S7: 466 | T7: 420 | U7: 527 | V7: 462 | W7: 517 | X7: 455 | Y7: 474 | Z7: 496 | AA7: 482 | AB7: 434 | AC7: 469 | AD7: 497 | AE7: 427 | AF7: 416 | AG7: 440 | AH7: 407 | AI7: 360 | AJ7: 593 | AK7: 513 | AL7: 482 | AM7: 546 | AN7: 4257 | AO7: 519 | AP7: 478 | AQ7: 513 | AR7: 544 | AS7: 491 | AT7: 478 | AU7: 425 | AV7: 434 | AW7: 471 | AX7: 443 | AY7: 479 | AZ7: 498 | BA7: 512 | BB7: 457 | BC7: 494 | BD7: 422 | BE7: 493 | BF7: 488 | BG7: 470 | BH7: 4472 | BI7: 384 | BJ7: 431 | BK7: 458 | BL7: 429 | BM7: 430 | BN7: 400 | BO7: 390 | BP7: 171492 | BQ7: Treponema | BR7: Treponema pallidum
A8: 7 | B8: K3 | F8: -1 | G8: 2 | H8: 2 | I8: 2 | J8: 1 | K8: 1 | L8: 8 | M8: 3 | N8: SS14-like | O8: 10110 | P8: 585 | Q8: 525 | R8: 552 | S8: 466 | T8: 420 | U8: 527 | V8: 462 | W8: 517 | X8: 455 | Y8: 474 | Z8: 496 | AA8: 482 | AB8: 434 | AC8: 469 | AD8: 497 | AE8: 427 | AF8: 416 | AG8: 440 | AH8: 407 | AI8: 360 | AJ8: 593 | AK8: 513 | AL8: 482 | AM8: 546 | AN8: 4257 | AO8: 519 | AP8: 478 | AQ8: 513 | AR8: 544 | AS8: 491 | AT8: 478 | AU8: 425 | AV8: 434 | AW8: 471 | AX8: 443 | AY8: 479 | AZ8: 498 | BA8: 512 | BB8: 457 | BC8: 494 | BD8: 422 | BE8: 493 | BF8: 488 | BG8: 470 | BH8: 4472 | BI8: 384 | BJ8: 431 | BK8: 458 | BL8: 429 | BM8: 430 | BN8: 400 | BO8: 390 | BP8: 171492 | BQ8: Treponema | BR8: Treponema pallidum
A9: 8 | B9: Q3 | F9: -1 | G9: 2 | H9: 2 | I9: 2 | J9: 1 | K9: 1 | L9: 8 | M9: 3 | N9: SS14-like | O9: 10110 | P9: 585 | Q9: 525 | R9: 552 | S9: 466 | T9: 420 | U9: 527 | V9: 462 | W9: 517 | X9: 455 | Y9: 474 | Z9: 496 | AA9: 482 | AB9: 434 | AC9: 469 | AD9: 497 | AE9: 427 | AF9: 416 | AG9: 440 | AH9: 407 | AI9: 360 | AJ9: 593 | AK9: 513 | AL9: 482 | AM9: 546 | AN9: 4257 | AO9: 519 | AP9: 478 | AQ9: 513 | AR9: 544 | AS9: 491 | AT9: 478 | AU9: 425 | AV9: 434 | AW9: 471 | AX9: 443 | AY9: 479 | AZ9: 498 | BA9: 512 | BB9: 457 | BC9: 494 | BD9: 422 | BE9: 493 | BF9: 488 | BG9: 470 | BH9: 4472 | BI9: 384 | BJ9: 431 | BK9: 458 | BL9: 429 | BM9: 430 | BN9: 400 | BO9: 390 | BP9: 171492 | BQ9: Treponema | BR9: Treponema pallidum
A10: 9 | B10: PT_SIF1348 | F10: -1 | G10: 2 | H10: 4 | I10: 3 | J10: 1 | K10: 3 | L10: 1 | M10: 1 | N10: SS14-like | O10: 10110 | P10: 585 | Q10: 525 | R10: 552 | S10: 466 | T10: 420 | U10: 527 | V10: 462 | W10: 517 | X10: 455 | Y10: 474 | Z10: 496 | AA10: 482 | AB10: 434 | AC10: 469 | AD10: 497 | AE10: 427 | AF10: 416 | AG10: 440 | AH10: 407 | AI10: 360 | AJ10: 593 | AK10: 513 | AL10: 482 | AM10: 546 | AN10: 4257 | AO10: 519 | AP10: 478 | AQ10: 513 | AR10: 544 | AS10: 491 | AT10: 478 | AU10: 425 | AV10: 434 | AW10: 471 | AX10: 443 | AY10: 479 | AZ10: 498 | BA10: 512 | BB10: 457 | BC10: 494 | BD10: 422 | BE10: 493 | BF10: 488 | BG10: 470 | BH10: 4472 | BI10: 384 | BJ10: 431 | BK10: 458 | BL10: 429 | BM10: 430 | BN10: 400 | BO10: 390 | BP10: 171492 | BQ10: Treponema | BR10: Treponema pallidum
A11: 10 | B11: PT_SIF1127 | F11: -1 | G11: 2 | H11: 4 | I11: 3 | J11: 1 | K11: 3 | L11: 1 | M11: 1 | N11: SS14-like | O11: 10110 | P11: 585 | Q11: 525 | R11: 552 | S11: 466 | T11: 420 | U11: 527 | V11: 462 | W11: 517 | X11: 455 | Y11: 474 | Z11: 496 | AA11: 482 | AB11: 434 | AC11: 469 | AD11: 497 | AE11: 427 | AF11: 416 | AG11: 440 | AH11: 407 | AI11: 360 | AJ11: 593 | AL11: 482 | AM11: 546 | AN11: 4257 | AO11: 519 | AP11: 478 | AQ11: 513 | AR11: 544 | AS11: 491 | AT11: 478 | AU11: 425 | AV11: 434 | AW11: 471 | AX11: 443 | AY11: 479 | AZ11: 498 | BA11: 512 | BB11: 457 | BC11: 494 | BD11: 422 | BE11: 493 | BF11: 488 | BG11: 470 | BH11: 4472 | BI11: 384 | BJ11: 431 | BK11: 458 | BL11: 429 | BM11: 430 | BN11: 400 | BO11: 390
A12: 11 | B12: PT_SIF1135 | F12: -1 | G12: 2 | H12: 2 | I12: 3 | J12: 1 | K12: 1 | L12: 1 | M12: 2 | N12: SS14-like | O12: 10110 | P12: 585 | Q12: 525 | R12: 552 | S12: 466 | T12: 420 | U12: 527 | V12: 462 | W12: 517 | X12: 455 | Y12: 474 | Z12: 496 | AA12: 482 | AB12: 434 | AC12: 469 | AD12: 497 | AE12: 427 | AF12: 416 | AG12: 440 | AH12: 407 | AI12: 360 | AJ12: 593 | AK12: 513 | AL12: 482 | AM12: 546 | AN12: 4257 | AO12: 519 | AP12: 478 | AQ12: 513 | AR12: 544 | AS12: 491 | AT12: 478 | AU12: 425 | AV12: 434 | AW12: 471 | AX12: 443 | AY12: 479 | AZ12: 498 | BA12: 512 | BB12: 457 | BC12: 494 | BD12: 422 | BE12: 493 | BF12: 488 | BG12: 470 | BH12: 4472 | BI12: 384 | BJ12: 431 | BK12: 458 | BL12: 429 | BM12: 430 | BN12: 400 | BO12: 390 | BP12: 171492 | BQ12: Treponema | BR12: Treponema pallidum
A13: 12 | B13: PT_SIF1140 | F13: -1 | G13: 2 | H13: 4 | I13: 3 | J13: 1 | K13: 3 | L13: 1 | M13: 1 | N13: SS14-like | O13: 10110 | Q13: 525 | R13: 552 | S13: 466 | T13: 420 | U13: 527 | V13: 462 | W13: 517 | X13: 455 | Y13: 474 | Z13: 496 | AA13: 482 | AB13: 434 | AC13: 469 | AD13: 497 | AE13: 427 | AF13: 416 | AG13: 440 | AH13: 407 | AI13: 360 | AJ13: 593 | AK13: 513 | AL13: 482 | AM13: 546 | AN13: 4257 | AO13: 519 | AP13: 478 | AQ13: 513 | AR13: 544 | AS13: 491 | AT13: 478 | AU13: 425 | AV13: 434 | AW13: 471 | AX13: 443 | AY13: 479 | AZ13: 498 | BA13: 512 | BB13: 457 | BC13: 494 | BD13: 422 | BE13: 493 | BF13: 488 | BG13: 470 | BH13: 4472 | BI13: 384 | BJ13: 431 | BK13: 458 | BL13: 429 | BM13: 430 | BN13: 400 | BO13: 390
A14: 13 | B14: PT_SIF1142 | F14: -1 | G14: 2 | H14: 4 | I14: 3 | J14: 1 | K14: 3 | L14: 1 | M14: 1 | N14: SS14-like | O14: 10110 | P14: 585 | Q14: 525 | R14: 552 | S14: 466 | T14: 420 | U14: 527 | V14: 462 | W14: 517 | X14: 455 | Y14: 474 | Z14: 496 | AA14: 482 | AB14: 434 | AC14: 469 | AD14: 497 | AE14: 427 | AF14: 416 | AG14: 440 | AH14: 407 | AI14: 360 | AJ14: 593 | AK14: 513 | AL14: 482 | AM14: 546 | AN14: 4257 | AO14: 519 | AP14: 478 | AQ14: 513 | AR14: 544 | AS14: 491 | AT14: 478 | AU14: 425 | AV14: 434 | AW14: 471 | AX14: 443 | AY14: 479 | AZ14: 498 | BA14: 512 | BB14: 457 | BC14: 494 | BD14: 422 | BE14: 493 | BF14: 488 | BG14: 470 | BH14: 4472 | BI14: 384 | BJ14: 431 | BK14: 458 | BL14: 429 | BM14: 430 | BN14: 400 | BO14: 390 | BP14: 171492 | BQ14: Treponema | BR14: Treponema pallidum
A15: 14 | B15: PT_SIF1156 | F15: -1 | G15: 2 | H15: 2 | I15: 3 | J15: 1 | K15: 1 | L15: 1 | M15: 2 | N15: SS14-like | O15: 10110 | P15: 585 | Q15: 525 | R15: 552 | S15: 466 | T15: 420 | U15: 527 | V15: 462 | W15: 517 | X15: 455 | Y15: 474 | Z15: 496 | AA15: 482 | AB15: 434 | AC15: 469 | AD15: 497 | AE15: 427 | AF15: 416 | AG15: 440 | AH15: 407 | AI15: 360 | AJ15: 593 | AK15: 513 | AL15: 482 | AM15: 546 | AN15: 4257 | AO15: 519 | AP15: 478 | AQ15: 513 | AR15: 544 | AS15: 491 | AT15: 478 | AU15: 425 | AV15: 434 | AW15: 471 | AX15: 443 | AY15: 479 | AZ15: 498 | BA15: 512 | BB15: 457 | BC15: 494 | BD15: 422 | BE15: 493 | BF15: 488 | BG15: 470 | BH15: 4472 | BI15: 384 | BJ15: 431 | BK15: 458 | BL15: 429 | BM15: 430 | BN15: 400 | BO15: 390 | BP15: 171492 | BQ15: Treponema | BR15: Treponema pallidum
A16: 15 | B16: PT_SIF1167 | F16: -1 | G16: 2 | H16: 2 | I16: 3 | J16: 1 | K16: 1 | L16: 1 | M16: 2 | N16: SS14-like | O16: 10110 | P16: 585 | Q16: 525 | R16: 552 | S16: 466 | T16: 420 | U16: 527 | V16: 462 | W16: 517 | X16: 455 | Y16: 474 | Z16: 496 | AA16: 482 | AB16: 434 | AC16: 469 | AD16: 497 | AE16: 427 | AF16: 416 | AG16: 440 | AH16: 407 | AI16: 360 | AJ16: 593 | AK16: 513 | AL16: 482 | AM16: 546 | AN16: 4257 | AO16: 519 | AP16: 478 | AQ16: 513 | AR16: 544 | AS16: 491 | AT16: 478 | AU16: 425 | AV16: 434 | AW16: 471 | AX16: 443 | AY16: 479 | AZ16: 498 | BA16: 512 | BB16: 457 | BC16: 494 | BD16: 422 | BE16: 493 | BF16: 488 | BG16: 470 | BH16: 4472 | BI16: 384 | BJ16: 431 | BK16: 458 | BL16: 429 | BM16: 430 | BN16: 400 | BO16: 390 | BP16: 171492 | BQ16: Treponema | BR16: Treponema pallidum
A17: 16 | B17: PT_SIF1183 | F17: -1 | G17: 2 | H17: 2 | I17: 3 | J17: 1 | K17: 1 | L17: 1 | M17: 2 | N17: SS14-like | O17: 10110 | P17: 585 | Q17: 525 | R17: 552 | S17: 466 | T17: 420 | U17: 527 | V17: 462 | W17: 517 | X17: 455 | Y17: 474 | Z17: 496 | AA17: 482 | AB17: 434 | AC17: 469 | AD17: 497 | AE17: 427 | AF17: 416 | AG17: 440 | AH17: 407 | AI17: 360 | AJ17: 593 | AK17: 513 | AL17: 482 | AM17: 546 | AN17: 4257 | AO17: 519 | AP17: 478 | AQ17: 513 | AR17: 544 | AS17: 491 | AT17: 478 | AU17: 425 | AV17: 434 | AW17: 471 | AX17: 443 | AY17: 479 | AZ17: 498 | BA17: 512 | BB17: 457 | BC17: 494 | BD17: 422 | BE17: 493 | BF17: 488 | BG17: 470 | BH17: 4472 | BI17: 384 | BJ17: 431 | BK17: 458 | BL17: 429 | BM17: 430 | BN17: 400 | BO17: 390 | BP17: 171492 | BQ17: Treponema | BR17: Treponema pallidum
A18: 17 | B18: PT_SIF1196 | F18: -1 | G18: 3 | H18: 2 | I18: 4 | J18: 7 | K18: 1 | L18: 9 | M18: 4 | N18: SS14-like | O18: 10110 | P18: 585 | Q18: 525 | R18: 552 | S18: 466 | T18: 420 | U18: 527 | V18: 462 | W18: 517 | X18: 455 | Y18: 474 | Z18: 496 | AA18: 482 | AB18: 434 | AC18: 469 | AD18: 497 | AE18: 427 | AF18: 416 | AG18: 440 | AH18: 407 | AI18: 360 | AJ18: 593 | AK18: 513 | AL18: 482 | AM18: 546 | AN18: 4257 | AO18: 519 | AP18: 478 | AQ18: 513 | AR18: 544 | AS18: 491 | AT18: 478 | AU18: 425 | AV18: 434 | AW18: 471 | AX18: 443 | AY18: 479 | AZ18: 498 | BA18: 512 | BB18: 457 | BC18: 494 | BD18: 422 | BE18: 493 | BF18: 488 | BG18: 470 | BH18: 4472 | BI18: 384 | BJ18: 431 | BK18: 458 | BL18: 429 | BM18: 430 | BN18: 400 | BO18: 390 | BP18: 171492 | BQ18: Treponema | BR18: Treponema pallidum
A19: 18 | B19: PT_SIF1200 | F19: -1 | G19: 2 | H19: 4 | I19: 5 | J19: 1 | K19: 3 | L19: 1 | M19: 1 | N19: SS14-like | O19: 10110 | P19: 585 | Q19: 525 | R19: 552 | S19: 466 | T19: 420 | U19: 527 | V19: 462 | W19: 517 | X19: 455 | Y19: 474 | Z19: 496 | AA19: 482 | AB19: 434 | AC19: 469 | AD19: 497 | AE19: 427 | AF19: 416 | AG19: 440 | AH19: 407 | AI19: 360 | AJ19: 593 | AK19: 513 | AL19: 482 | AM19: 546 | AN19: 4257 | AO19: 519 | AP19: 478 | AQ19: 513 | AR19: 544 | AS19: 491 | AT19: 478 | AU19: 425 | AV19: 434 | AW19: 471 | AX19: 443 | AY19: 479 | AZ19: 498 | BA19: 512 | BB19: 457 | BC19: 494 | BD19: 422 | BE19: 493 | BF19: 488 | BG19: 470 | BH19: 4472 | BI19: 384 | BJ19: 431 | BK19: 458 | BL19: 429 | BM19: 430 | BN19: 400 | BO19: 390 | BP19: 171492 | BQ19: Treponema | BR19: Treponema pallidum
A20: 19 | B20: PT_SIF1242 | F20: -1 | G20: 4 | H20: 2 | I20: 4 | J20: 7 | K20: 1 | L20: 9 | M20: 4 | N20: SS14-like | O20: 10110 | P20: 585 | Q20: 525 | R20: 552 | S20: 466 | T20: 420 | U20: 527 | V20: 462 | W20: 517 | X20: 455 | Y20: 474 | Z20: 496 | AA20: 482 | AB20: 434 | AC20: 469 | AD20: 497 | AE20: 427 | AF20: 416 | AG20: 440 | AH20: 407 | AI20: 360 | AJ20: 593 | AK20: 513 | AL20: 482 | AM20: 546 | AN20: 4257 | AO20: 519 | AP20: 478 | AQ20: 513 | AR20: 544 | AS20: 491 | AT20: 478 | AU20: 425 | AV20: 434 | AW20: 471 | AX20: 443 | AY20: 479 | AZ20: 498 | BA20: 512 | BB20: 457 | BC20: 494 | BD20: 422 | BE20: 493 | BF20: 488 | BG20: 470 | BH20: 4472 | BI20: 384 | BJ20: 431 | BK20: 458 | BL20: 429 | BM20: 430 | BN20: 400 | BO20: 390 | BP20: 171492 | BQ20: Treponema | BR20: Treponema pallidum
A21: 20 | B21: PT_SIF1299 | F21: -1 | G21: 2 | H21: 4 | I21: 3 | J21: 1 | K21: 3 | L21: 1 | M21: 1 | N21: SS14-like | O21: 10110 | P21: 585 | Q21: 525 | R21: 552 | S21: 466 | T21: 420 | U21: 527 | V21: 462 | W21: 517 | X21: 455 | Y21: 474 | Z21: 496 | AA21: 482 | AB21: 434 | AC21: 469 | AD21: 497 | AE21: 427 | AF21: 416 | AG21: 440 | AH21: 407 | AI21: 360 | AJ21: 593 | AK21: 513 | AL21: 482 | AM21: 546 | AN21: 4257 | AO21: 519 | AP21: 478 | AQ21: 513 | AR21: 544 | AS21: 491 | AT21: 478 | AU21: 425 | AV21: 434 | AW21: 471 | AX21: 443 | AY21: 479 | AZ21: 498 | BA21: 512 | BB21: 457 | BC21: 494 | BD21: 422 | BE21: 493 | BF21: 488 | BG21: 470 | BH21: 4472 | BI21: 384 | BJ21: 431 | BK21: 458 | BL21: 429 | BM21: 430 | BN21: 400 | BO21: 390 | BP21: 171492 | BQ21: Treponema | BR21: Treponema pallidum
A22: 21 | B22: PT_SIF1252 | F22: -1 | G22: 2 | H22: 4 | I22: 3 | J22: 1 | K22: 3 | L22: 1 | M22: 1 | N22: SS14-like | O22: 10110 | P22: 585 | Q22: 525 | R22: 552 | S22: 466 | T22: 420 | U22: 527 | V22: 462 | W22: 517 | X22: 455 | Y22: 474 | Z22: 496 | AA22: 482 | AB22: 434 | AC22: 469 | AD22: 497 | AE22: 427 | AF22: 416 | AG22: 440 | AH22: 407 | AI22: 360 | AJ22: 593 | AK22: 513 | AL22: 482 | AM22: 546 | AN22: 4257 | AO22: 519 | AP22: 478 | AQ22: 513 | AR22: 544 | AS22: 491 | AT22: 478 | AU22: 425 | AV22: 434 | AW22: 471 | AX22: 443 | AY22: 479 | AZ22: 498 | BA22: 512 | BB22: 457 | BC22: 494 | BD22: 422 | BE22: 493 | BF22: 488 | BG22: 470 | BH22: 4472 | BI22: 384 | BJ22: 431 | BK22: 458 | BL22: 429 | BM22: 430 | BN22: 400 | BO22: 390 | BP22: 171492 | BQ22: Treponema | BR22: Treponema pallidum
A23: 22 | B23: PT_SIF1261 | F23: -1 | G23: 2 | H23: 4 | I23: 3 | J23: 1 | K23: 3 | L23: 1 | M23: 1 | N23: SS14-like | O23: 10110 | P23: 585 | Q23: 525 | R23: 552 | S23: 466 | T23: 420 | U23: 527 | V23: 462 | W23: 517 | X23: 455 | Y23: 474 | Z23: 496 | AA23: 482 | AB23: 434 | AC23: 469 | AD23: 497 | AE23: 427 | AF23: 416 | AG23: 440 | AH23: 407 | AI23: 360 | AJ23: 593 | AK23: 513 | AL23: 482 | AM23: 546 | AN23: 4257 | AO23: 519 | AP23: 478 | AQ23: 513 | AR23: 544 | AS23: 491 | AT23: 478 | AU23: 425 | AV23: 434 | AW23: 471 | AX23: 443 | AY23: 479 | AZ23: 498 | BA23: 512 | BB23: 457 | BC23: 494 | BD23: 422 | BE23: 493 | BF23: 488 | BG23: 470 | BH23: 4472 | BI23: 384 | BJ23: 431 | BK23: 458 | BL23: 429 | BM23: 430 | BN23: 400 | BO23: 390 | BP23: 171492 | BQ23: Treponema | BR23: Treponema pallidum
A24: 23 | B24: PT_SIF1278 | F24: -1 | G24: 2 | H24: 4 | I24: 3 | J24: 1 | K24: 3 | L24: 1 | M24: 1 | N24: SS14-like | O24: 10110 | P24: 585 | Q24: 525 | R24: 552 | S24: 466 | T24: 420 | U24: 527 | V24: 462 | W24: 517 | X24: 455 | Y24: 474 | Z24: 496 | AA24: 482 | AB24: 434 | AC24: 469 | AD24: 497 | AE24: 427 | AF24: 416 | AG24: 440 | AH24: 407 | AI24: 360 | AJ24: 593 | AK24: 513 | AL24: 482 | AM24: 546 | AN24: 4257 | AO24: 519 | AP24: 478 | AQ24: 513 | AR24: 544 | AS24: 491 | AT24: 478 | AU24: 425 | AV24: 434 | AW24: 471 | AX24: 443 | AY24: 479 | AZ24: 498 | BA24: 512 | BB24: 457 | BC24: 494 | BD24: 422 | BE24: 493 | BF24: 488 | BG24: 470 | BH24: 4472 | BI24: 384 | BJ24: 431 | BK24: 458 | BL24: 429 | BM24: 430 | BN24: 400 | BO24: 390 | BP24: 171492 | BQ24: Treponema | BR24: Treponema pallidum
A25: 24 | B25: PT_SIF1280 | F25: -1 | G25: 2 | H25: 4 | I25: 3 | J25: 1 | K25: 3 | L25: 1 | M25: 1 | N25: SS14-like | O25: 10110 | P25: 585 | Q25: 525 | R25: 552 | S25: 466 | T25: 420 | U25: 527 | V25: 462 | W25: 517 | X25: 455 | Y25: 474 | Z25: 496 | AA25: 482 | AB25: 434 | AC25: 469 | AD25: 497 | AE25: 427 | AF25: 416 | AG25: 440 | AH25: 407 | AI25: 360 | AJ25: 593 | AK25: 513 | AL25: 482 | AM25: 546 | AN25: 4257 | AO25: 519 | AP25: 478 | AQ25: 513 | AR25: 544 | AS25: 491 | AT25: 478 | AU25: 425 | AV25: 434 | AW25: 471 | AX25: 443 | AY25: 479 | AZ25: 498 | BA25: 512 | BB25: 457 | BC25: 494 | BD25: 422 | BE25: 493 | BF25: 488 | BG25: 470 | BH25: 4472 | BI25: 384 | BJ25: 431 | BK25: 458 | BL25: 429 | BM25: 430 | BN25: 400 | BO25: 390 | BP25: 171492 | BQ25: Treponema | BR25: Treponema pallidum
... A38: 134 | B38: Mexico A | F38: -1 | G38: 5 | H38: 3 | I38: 1 | J38: 1 | K38: 13 | L38: 10 | M38: 21 | N38: SS14-like | O38: 10110 | P38: 585 | Q38: 525 | R38: 552 | S38: 466 | T38: 420 | U38: 527 | V38: 462 | W38: 517 | X38: 455 | Y38: 474 | Z38: 496 | AA38: 482 | AB38: 434 | AC38: 469 | AD38: 497 | AE38: 427 | AF38: 416 | AG38: 440 | AH38: 407 | AI38: 360 | AJ38: 593 | AK38: 513 | AL38: 482 | AM38: 546 | AN38: 4257 | AO38: 519 | AP38: 478 | AQ38: 513 | AR38: 544 | AS38: 491 | AT38: 478 | AU38: 425 | AV38: 434 | AW38: 471 | AX38: 443 | AY38: 479 | AZ38: 498 | BA38: 512 | BB38: 457 | BC38: 494 | BD38: 422 | BE38: 493 | BF38: 488 | BG38: 470 | BH38: 4472 | BI38: 384 | BJ38: 431 | BK38: 458 | BL38: 429 | BM38: 430 | BN38: 400 | BO38: 390 | BP38: 171492 | BQ38: Treponema | BR38: Treponema pallidum
A39: 135 | B39: DAL-1 | F39: -1 | H39: 1 | I39: 1 | J39: 11 | K39: 14 | L39: 10 | M39: 22 | N39: Nichols-like | O39: 10110 | P39: 585 | Q39: 525 | R39: 552 | S39: 466 | T39: 420 | U39: 527 | V39: 462 | W39: 517 | X39: 455 | Y39: 474 | Z39: 496 | AA39: 482 | AB39: 434 | AC39: 469 | AD39: 497 | AE39: 427 | AF39: 416 | AG39: 440 | AH39: 407 | AI39: 360 | AJ39: 593 | AK39: 513 | AL39: 482 | AM39: 546 | AN39: 4257 | AO39: 519 | AP39: 478 | AQ39: 513 | AR39: 544 | AS39: 491 | AT39: 478 | AU39: 425 | AV39: 434 | AW39: 471 | AX39: 443 | AY39: 479 | AZ39: 498 | BA39: 512 | BB39: 457 | BC39: 494 | BD39: 422 | BE39: 493 | BF39: 488 | BG39: 470 | BH39: 4472 | BI39: 384 | BJ39: 431 | BK39: 458 | BL39: 429 | BM39: 430 | BN39: 400 | BO39: 390 | BP39: 171492 | BQ39: Treponema | BR39: Treponema pallidum
A40: 136 | B40: SEA81-4 | F40: -1 | H40: 5 | I40: 1 | J40: 12 | K40: 15 | L40: 10 | M40: 23 | N40: Nichols-like | O40: 10110 | P40: 585 | Q40: 525 | R40: 552 | S40: 15259 | T40: 420 | U40: 527 | V40: 462 | W40: 517 | X40: 455 | Y40: 474 | Z40: 496 | AA40: 482 | AB40: 434 | AC40: 469 | AD40: 497 | AE40: 427 | AF40: 416 | AG40: 440 | AH40: 407 | AI40: 360 | AJ40: 593 | AK40: 513 | AL40: 482 | AM40: 546 | AN40: 4257 | AO40: 519 | AP40: 478 | AQ40: 513 | AR40: 544 | AS40: 491 | AT40: 478 | AU40: 425 | AV40: 434 | AW40: 471 | AX40: 443 | AY40: 479 | AZ40: 498 | BA40: 512 | BB40: 457 | BC40: 494 | BD40: 422 | BE40: 493 | BF40: 488 | BG40: 470 | BH40: 4472 | BI40: 384 | BJ40: 431 | BK40: 458 | BL40: 429 | BM40: 430 | BN40: 400 | BO40: 390 | BP40: 49890 | BQ40: Treponema | BR40: Treponema pallidum
A41: 137 | B41: Amoy | F41: -1 | H41: 2 | I41: 2 | J41: 6 | K41: 1 | L41: 8 | M41: 24 | N41: SS14-like | O41: 10110 | P41: 585 | Q41: 525 | R41: 552 | S41: 466 | T41: 420 | U41: 527 | V41: 462 | W41: 517 | X41: 455 | Y41: 474 | Z41: 496 | AA41: 482 | AB41: 434 | AC41: 469 | AD41: 497 | AE41: 427 | AF41: 416 | AG41: 440 | AH41: 407 | AI41: 360 | AJ41: 593 | AK41: 513 | AL41: 482 | AM41: 546 | AN41: 4257 | AO41: 519 | AP41: 478 | AQ41: 513 | AR41: 544 | AS41: 491 | AT41: 478 | AU41: 425 | AV41: 434 | AW41: 471 | AX41: 443 | AY41: 479 | AZ41: 498 | BA41: 512 | BB41: 457 | BC41: 494 | BD41: 422 | BE41: 493 | BF41: 488 | BG41: 470 | BH41: 4472 | BI41: 384 | BJ41: 431 | BK41: 458 | BL41: 429 | BM41: 430 | BN41: 400 | BO41: 390 | BP41: 171492 | BQ41: Treponema | BR41: Treponema pallidum
A42: 138 | B42: UZ1974 | F42: -1 | G42: 2 | H42: 6 | I42: 3 | J42: 1 | K42: 26 | L42: 1 | M42: 25 | N42: SS14-like | O42: 10110 | P42: 585 | Q42: 525 | R42: 552 | S42: 466 | T42: 420 | U42: 527 | V42: 462 | W42: 517 | X42: 455 | Y42: 474 | Z42: 496 | AA42: 482 | AB42: 434 | AC42: 469 | AD42: 497 | AE42: 427 | AF42: 416 | AG42: 440 | AH42: 407 | AI42: 360 | AJ42: 593 | AK42: 513 | AL42: 482 | AM42: 546 | AN42: 4257 | AO42: 519 | AP42: 478 | AQ42: 513 | AR42: 544 | AS42: 491 | AT42: 478 | AU42: 425 | AV42: 434 | AW42: 471 | AX42: 443 | AY42: 479 | AZ42: 498 | BA42: 512 | BB42: 457 | BC42: 494 | BD42: 422 | BE42: 493 | BF42: 488 | BG42: 470 | BH42: 4472 | BI42: 384 | BJ42: 431 | BK42: 458 | BL42: 429 | BM42: 430 | BN42: 400 | BO42: 390 | BP42: 171492 | BQ42: Treponema | BR42: Treponema pallidum
A43: 139 | B43: ARG2 | F43: -1 | P43: 585 | R43: 552 | S43: 466 | T43: 420 | U43: 527 | V43: 462 | W43: 517 | X43: 455 | Y43: 474 | Z43: 496 | AA43: 482 | AC43: 469 | AD43: 497 | AE43: 427 | AF43: 416 | AG43: 440 | AH43: 407 | AI43: 360 | AJ43: 593 | AN43: 4257 | AO43: 519 | AP43: 478 | AQ43: 513 | AS43: 491 | AT43: 478 | AU43: 425 | AX43: 443 | AY43: 479 | AZ43: 498 | BA43: 512 | BB43: 457 | BE43: 493 | BF43: 488 | BJ43: 431 | BK43: 458 | BL43: 429 | BM43: 430 | BN43: 400 | BO43: 390
A44: 140 | B44: AU15 | F44: -1 | O44: 10110 | P44: 585 | Q44: 525 | R44: 552 | S44: 466 | T44: 420 | U44: 527 | V44: 462 | W44: 517 | X44: 455 | Y44: 474 | AB44: 434 | AC44: 469 | AD44: 497 | AE44: 427 | AF44: 416 | AG44: 440 | AH44: 407 | AI44: 360 | AJ44: 593 | AK44: 513 | AL44: 482 | AM44: 546 | AN44: 4257 | AO44: 519 | AP44: 478 | AQ44: 513 | AR44: 544 | AS44: 491 | AT44: 478 | AU44: 425 | AV44: 434 | AW44: 471 | AX44: 443 | AY44: 479 | AZ44: 498 | BA44: 512 | BC44: 494 | BD44: 422 | BE44: 493 | BF44: 488 | BH44: 4472 | BI44: 384 | BJ44: 431 | BK44: 458 | BL44: 429 | BM44: 430 | BN44: 400 | BO44: 390
A45: 141 | B45: AU16 | F45: -1 | R45: 552 | T45: 420 | U45: 527 | V45: 462 | W45: 517 | X45: 455 | Y45: 474 | AA45: 482 | AB45: 434 | AC45: 469 | AD45: 497 | AE45: 427 | AF45: 416 | AG45: 440 | AH45: 407 | AI45: 360 | AK45: 513 | AL45: 482 | AM45: 546 | AN45: 4257 | AP45: 478 | AQ45: 513 | AS45: 491 | AT45: 478 | AV45: 434 | AW45: 471 | AX45: 443 | AZ45: 498 | BB45: 457 | BC45: 494 | BD45: 422 | BE45: 493 | BF45: 488 | BI45: 384 | BJ45: 431 | BK45: 458 | BL45: 429 | BM45: 430 | BN45: 400 | BO45: 390
A46: 142 | B46: AU17 | F46: -1 | P46: 585 | S46: 466 | T46: 420 | AA46: 482 | AD46: 497 | AF46: 416 | AG46: 440 | AI46: 360 | AL46: 482 | AQ46: 513 | AU46: 425 | BC46: 494 | BN46: 400 | BO46: 390
A47: 143 | B47: CZ27 | F47: -1 | G47: 2 | H47: 2 | I47: 2 | J47: 1 | K47: 1 | L47: 8 | M47: 3 | N47: SS14-like | O47: 10110 | P47: 585 | Q47: 525 | R47: 552 | S47: 466 | T47: 420 | U47: 527 | V47: 462 | W47: 517 | X47: 455 | Y47: 474 | Z47: 496 | AA47: 482 | AB47: 434 | AC47: 469 | AD47: 497 | AE47: 427 | AF47: 416 | AG47: 440 | AH47: 407 | AI47: 360 | AJ47: 593 | AK47: 513 | AL47: 482 | AM47: 546 | AN47: 4257 | AO47: 519 | AP47: 478 | AQ47: 513 | AR47: 544 | AS47: 491 | AT47: 478 | AU47: 425 | AV47: 434 | AW47: 471 | AX47: 443 | AY47: 479 | AZ47: 498 | BA47: 512 | BB47: 457 | BC47: 494 | BD47: 422 | BE47: 493 | BF47: 488 | BG47: 470 | BH47: 4472 | BI47: 384 | BJ47: 431 | BK47: 458 | BL47: 429 | BM47: 430 | BN47: 400 | BO47: 390 | BP47: 171492 | BQ47: Treponema | BR47: Treponema pallidum
A48: 144 | B48: Grady | F48: -1 | G48: 2 | H48: 2 | I48: 3 | J48: 1 | K48: 1 | L48: 1 | M48: 2 | N48: SS14-like | O48: 10110 | P48: 585 | Q48: 525 | R48: 552 | S48: 466 | T48: 420 | U48: 527 | V48: 462 | W48: 517 | X48: 455 | Y48: 474 | Z48: 496 | AA48: 482 | AB48: 434 | AC48: 469 | AD48: 497 | AE48: 427 | AF48: 416 | AG48: 440 | AH48: 407 | AI48: 360 | AJ48: 593 | AK48: 513 | AL48: 482 | AM48: 546 | AN48: 4257 | AO48: 519 | AP48: 478 | AQ48: 513 | AR48: 544 | AS48: 491 | AT48: 478 | AU48: 425 | AV48: 434 | AW48: 471 | AX48: 443 | AY48: 479 | AZ48: 498 | BA48: 512 | BB48: 457 | BC48: 494 | BD48: 422 | BE48: 493 | BF48: 488 | BG48: 470 | BH48: 4472 | BI48: 384 | BJ48: 431 | BK48: 458 | BL48: 429 | BM48: 430 | BN48: 400 | BO48: 390 | BP48: 171492 | BQ48: Treponema | BR48: Treponema pallidum
A49: 145 | B49: NE12 | F49: -1 | T49: 420 | AQ49: 513 | BJ49: 431 | BL49: 429
A50: 146 | B50: NE15 | F50: -1 | O50: 10110 | Q50: 525 | T50: 420 | W50: 517 | AC50: 469 | AD50: 497 | AE50: 427 | AF50: 416 | AG50: 440 | AH50: 407 | AJ50: 593 | AN50: 4257 | AQ50: 513 | AT50: 478 | AU50: 425 | AV50: 434 | BC50: 494 | BE50: 493 | BI50: 384 | BJ50: 431 | BL50: 429 | BO50: 390
A51: 147 | B51: NE17 | F51: -1 | O51: 10110 | Q51: 525 | R51: 552 | S51: 466 | T51: 420 | U51: 527 | V51: 462 | W51: 517 | X51: 455 | Y51: 474 | AA51: 482 | AB51: 434 | AC51: 469 | AD51: 497 | AE51: 427 | AF51: 416 | AG51: 440 | AH51: 407 | AI51: 360 | AK51: 513 | AL51: 482 | AM51: 546 | AO51: 519 | AP51: 478 | AQ51: 513 | AS51: 491 | AT51: 478 | AU51: 425 | AV51: 434 | AW51: 471 | AX51: 443 | AY51: 479 | AZ51: 498 | BB51: 457 | BC51: 494 | BD51: 422 | BE51: 493 | BF51: 488 | BG51: 470 | BH51: 4472 | BI51: 384 | BJ51: 431 | BK51: 458 | BL51: 429 | BM51: 430 | BN51: 400 | BO51: 390
A52: 148 | B52: NE19 | F52: -1 | AI52: 360 | AU52: 425 | BN52: 400
...

Sheet simplified
A1: isolate | B1: run_accession | C1: TP0136 | D1: TP0548 | E1: TP0705 | F1: ST (MLST (Grillová))
A2: SHC_0 | C2: 1 | D2: 1 | E2: 8 | F2: 3
A3: SHD_R | C3: 1 | D3: 1 | E3: 8 | F3: 3
A4: SHE_V | C4: 1 | D4: 1 | E4: 8 | F4: 3
A5: SGF_12 | C5: 1 | D5: 1 | E5: 8 | F5: 3
A6: B3 | C6: 1 | D6: 1 | E6: 8 | F6: 3
A7: C3 | C7: 1 | E7: 8
A8: K3 | C8: 1 | D8: 1 | E8: 8 | F8: 3
A9: Q3 | C9: 1 | D9: 1 | E9: 8 | F9: 3
A10: PT_SIF1348 | C10: 1 | D10: 3 | E10: 1 | F10: 1
A11: PT_SIF1127 | C11: 1 | D11: 3 | E11: 1 | F11: 1
A12: PT_SIF1135 | C12: 1 | D12: 1 | E12: 1 | F12: 2
A13: PT_SIF1140 | C13: 1 | D13: 3 | E13: 1 | F13: 1
A14: PT_SIF1142 | C14: 1 | D14: 3 | E14: 1 | F14: 1
A15: PT_SIF1156 | C15: 1 | D15: 1 | E15: 1 | F15: 2
A16: PT_SIF1167 | C16: 1 | D16: 1 | E16: 1 | F16: 2
A17: PT_SIF1183 | C17: 1 | D17: 1 | E17: 1 | F17: 2
A18: PT_SIF1196 | C18: 7 | D18: 1 | E18: 9 | F18: 4
A19: PT_SIF1200 | C19: 1 | D19: 3 | E19: 1 | F19: 1
... A42: UZ1974 | C42: 1 | D42: 26 | E42: 1 | F42: 25
A43: ARG2
A44: AU15
A45: AU16
A46: AU17
A47: CZ27 | C47: 1 | D47: 1 | E47: 8 | F47: 3
A48: Grady | C48: 1 | D48: 1 | E48: 1 | F48: 2
A49: NE12
A50: NE15
A51: NE17
A52: NE19
A53: SW1
A54: SW4
A55: SW6
A56: SW8
A57: UW249B
A58: BAL3
A59: BAL73
A60: NE20 | C60: 9 | D60: 7
A61: SEA86-1
A62: Chicago-population | D62: 14 | E62: 10
...

Sheet matching
A1: Sample_Name | B1: SRR/ENA_Accession | C1: isolate | D1: run_accession | E1: TP0136 | F1: TP0548 | G1: TP0705 | H1: ST (MLST (Grillová))
A2: 17A003MM | B2: DRR213714 | C2: =VLOOKUP($A2,simplified!$A:$F,1,FALSE) -> 17A003MM | D2: =VLOOKUP($A2,simplified!$A:$F,2,FALSE) -> DRR213714 | E2: =VLOOKUP($A2,simplified!$A:$F,3,FALSE) -> 0 | F2: =VLOOKUP($A2,simplified!$A:$F,4,FALSE) -> 2 | G2: =VLOOKUP($A2,simplified!$A:$F,5,FALSE) -> 3 | H2: =VLOOKUP($A2,simplified!$A:$F,6,FALSE) -> 0
A3: 17A021MM | B3: DRR213718 | C3: =VLOOKUP($A3,simplified!$A:$F,1,FALSE) -> 17A021MM | D3: =VLOOKUP($A3,simplified!$A:$F,2,FALSE) -> DRR213718 | E3: =VLOOKUP($A3,simplified!$A:$F,3,FALSE) -> 0 | F3: =VLOOKUP($A3,simplified!$A:$F,4,FALSE) -> 16 | G3: =VLOOKUP($A3,simplified!$A:$F,5,FALSE) -> 0 | H3: =VLOOKUP($A3,simplified!$A:$F,6,FALSE) -> 0
A4: 17D002HM | B4: DRR213721 | C4: =VLOOKUP($A4,simplified!$A:$F,1,FALSE) -> 17D002HM | D4: =VLOOKUP($A4,simplified!$A:$F,2,FALSE) -> DRR213721 | E4: =VLOOKUP($A4,simplified!$A:$F,3,FALSE) -> 0 | F4: =VLOOKUP($A4,simplified!$A:$F,4,FALSE) -> 1 | G4: =VLOOKUP($A4,simplified!$A:$F,5,FALSE) -> 0 | H4: =VLOOKUP($A4,simplified!$A:$F,6,FALSE) -> 0
A5: 18E016HF | B5: DRR213730 | C5: =VLOOKUP($A5,simplified!$A:$F,1,FALSE) -> 18E016HF | D5: =VLOOKUP($A5,simplified!$A:$F,2,FALSE) -> DRR213730 | E5: =VLOOKUP($A5,simplified!$A:$F,3,FALSE) -> 0 | F5: =VLOOKUP($A5,simplified!$A:$F,4,FALSE) -> 1 | G5: =VLOOKUP($A5,simplified!$A:$F,5,FALSE) -> 0 | H5: =VLOOKUP($A5,simplified!$A:$F,6,FALSE) -> 0
A6: A10 | B6: - | C6: =VLOOKUP($A6,simplified!$A:$F,1,FALSE) -> A10 | D6: =VLOOKUP($A6,simplified!$A:$F,2,FALSE) -> SRR4308606 | E6: =VLOOKUP($A6,simplified!$A:$F,3,FALSE) -> 0 | F6: =VLOOKUP($A6,simplified!$A:$F,4,FALSE) -> 0 | G6: =VLOOKUP($A6,simplified!$A:$F,5,FALSE) -> 10 | H6: =VLOOKUP($A6,simplified!$A:$F,6,FALSE) -> 0
A7: A12 | B7: - | C7: =VLOOKUP($A7,simplified!$A:$F,1,FALSE) -> A12 | D7: =VLOOKUP($A7,simplified!$A:$F,2,FALSE) -> SRR4308607 | E7: =VLOOKUP($A7,simplified!$A:$F,3,FALSE) -> 0 | F7: =VLOOKUP($A7,simplified!$A:$F,4,FALSE) -> 0 | G7: =VLOOKUP($A7,simplified!$A:$F,5,FALSE) -> 10 | H7: =VLOOKUP($A7,simplified!$A:$F,6,FALSE) -> 0
A8: Amoy | B8: NZ_CP015162.1 | C8: =VLOOKUP($A8,simplified!$A:$F,1,FALSE) -> Amoy | D8: =VLOOKUP($A8,simplified!$A:$F,2,FALSE) -> 0 | E8: =VLOOKUP($A8,simplified!$A:$F,3,FALSE) -> 6 | F8: =VLOOKUP($A8,simplified!$A:$F,4,FALSE) -> 1 | G8: =VLOOKUP($A8,simplified!$A:$F,5,FALSE) -> 8 | H8: =VLOOKUP($A8,simplified!$A:$F,6,FALSE) -> 24
A9: AU15 | B9: SRR3268722 | C9: =VLOOKUP($A9,simplified!$A:$F,1,FALSE) -> AU15 | D9: =VLOOKUP($A9,simplified!$A:$F,2,FALSE) -> 0 | E9: =VLOOKUP($A9,simplified!$A:$F,3,FALSE) -> 0 | F9: =VLOOKUP($A9,simplified!$A:$F,4,FALSE) -> 0 | G9: =VLOOKUP($A9,simplified!$A:$F,5,FALSE) -> 0 | H9: =VLOOKUP($A9,simplified!$A:$F,6,FALSE) -> 0
A10: AU16 | B10: SRR3268723 | C10: =VLOOKUP($A10,simplified!$A:$F,1,FALSE) -> AU16 | D10: =VLOOKUP($A10,simplified!$A:$F,2,FALSE) -> 0 | E10: =VLOOKUP($A10,simplified!$A:$F,3,FALSE) -> 0 | F10: =VLOOKUP($A10,simplified!$A:$F,4,FALSE) -> 0 | G10: =VLOOKUP($A10,simplified!$A:$F,5,FALSE) -> 0 | H10: =VLOOKUP($A10,simplified!$A:$F,6,FALSE) -> 0
A11: B3 | B11: SRR2996728 | C11: =VLOOKUP($A11,simplified!$A:$F,1,FALSE) -> B3 | D11: =VLOOKUP($A11,simplified!$A:$F,2,FALSE) -> 0 | E11: =VLOOKUP($A11,simplified!$A:$F,3,FALSE) -> 1 | F11: =VLOOKUP($A11,simplified!$A:$F,4,FALSE) -> 1 | G11: =VLOOKUP($A11,simplified!$A:$F,5,FALSE) -> 8 | H11: =VLOOKUP($A11,simplified!$A:$F,6,FALSE) -> 3
A12: BAL3 | B12: SRR3268715 | C12: =VLOOKUP($A12,simplified!$A:$F,1,FALSE) -> BAL3 | D12: =VLOOKUP($A12,simplified!$A:$F,2,FALSE) -> 0 | E12: =VLOOKUP($A12,simplified!$A:$F,3,FALSE) -> 0 | F12: =VLOOKUP($A12,simplified!$A:$F,4,FALSE) -> 0 | G12: =VLOOKUP($A12,simplified!$A:$F,5,FALSE) -> 0 | H12: =VLOOKUP($A12,simplified!$A:$F,6,FALSE) -> 0
A13: BAL73 | B13: SRR3268726 | C13: =VLOOKUP($A13,simplified!$A:$F,1,FALSE) -> BAL73 | D13: =VLOOKUP($A13,simplified!$A:$F,2,FALSE) -> 0 | E13: =VLOOKUP($A13,simplified!$A:$F,3,FALSE) -> 0 | F13: =VLOOKUP($A13,simplified!$A:$F,4,FALSE) -> 0 | G13: =VLOOKUP($A13,simplified!$A:$F,5,FALSE) -> 0 | H13: =VLOOKUP($A13,simplified!$A:$F,6,FALSE) -> 0
... A388: UW391B | B388: ERR2756174 | C388: =VLOOKUP($A388,simplified!$A:$F,1,FALSE) -> UW391B | D388: =VLOOKUP($A388,simplified!$A:$F,2,FALSE) -> 0 | E388: =VLOOKUP($A388,simplified!$A:$F,3,FALSE) -> 1 | F388: =VLOOKUP($A388,simplified!$A:$F,4,FALSE) -> 1 | G388: =VLOOKUP($A388,simplified!$A:$F,5,FALSE) -> 9 | H388: =VLOOKUP($A388,simplified!$A:$F,6,FALSE) -> 27
A389: Amoy-X-4 | B389: SRR9127751 | C389: =VLOOKUP($B389,simplified!$B:$F,1,FALSE) -> #N/A | D389: =VLOOKUP($B389,simplified!$B:$F,1,FALSE) -> #N/A | E389: =VLOOKUP($B389,simplified!$B:$F,1,FALSE) -> #N/A | F389: =VLOOKUP($B389,simplified!$B:$F,1,FALSE) -> #N/A | G389: =VLOOKUP($B389,simplified!$B:$F,1,FALSE) -> #N/A | H389: =VLOOKUP($B389,simplified!$B:$F,1,FALSE) -> #N/A
A390: AR2 | B390: SRR3268682 | C390: =VLOOKUP($B390,simplified!$B:$F,1,FALSE) -> #N/A | D390: =VLOOKUP($B390,simplified!$B:$F,1,FALSE) -> #N/A | E390: =VLOOKUP($B390,simplified!$B:$F,1,FALSE) -> #N/A | F390: =VLOOKUP($B390,simplified!$B:$F,1,FALSE) -> #N/A | G390: =VLOOKUP($B390,simplified!$B:$F,1,FALSE) -> #N/A | H390: =VLOOKUP($B390,simplified!$B:$F,1,FALSE) -> #N/A
A391: BosniaA | B391: NZ_CP007548.1 | C391: =VLOOKUP($B391,simplified!$B:$F,1,FALSE) -> #N/A | D391: =VLOOKUP($B391,simplified!$B:$F,1,FALSE) -> #N/A | E391: =VLOOKUP($B391,simplified!$B:$F,1,FALSE) -> #N/A | F391: =VLOOKUP($B391,simplified!$B:$F,1,FALSE) -> #N/A | G391: =VLOOKUP($B391,simplified!$B:$F,1,FALSE) -> #N/A | H391: =VLOOKUP($B391,simplified!$B:$F,1,FALSE) -> #N/A
A392: IraqB | B392: CP032303.1 | C392: =VLOOKUP($B392,simplified!$B:$F,1,FALSE) -> #N/A | D392: =VLOOKUP($B392,simplified!$B:$F,1,FALSE) -> #N/A | E392: =VLOOKUP($B392,simplified!$B:$F,1,FALSE) -> #N/A | F392: =VLOOKUP($B392,simplified!$B:$F,1,FALSE) -> #N/A | G392: =VLOOKUP($B392,simplified!$B:$F,1,FALSE) -> #N/A | H392: =VLOOKUP($B392,simplified!$B:$F,1,FALSE) -> #N/A
A393: IraqB-mcf | B393: ERR5210583 | C393: =VLOOKUP($B393,simplified!$B:$F,1,FALSE) -> #N/A | D393: =VLOOKUP($B393,simplified!$B:$F,1,FALSE) -> #N/A | E393: =VLOOKUP($B393,simplified!$B:$F,1,FALSE) -> #N/A | F393: =VLOOKUP($B393,simplified!$B:$F,1,FALSE) -> #N/A | G393: =VLOOKUP($B393,simplified!$B:$F,1,FALSE) -> #N/A | H393: =VLOOKUP($B393,simplified!$B:$F,1,FALSE) -> #N/A
A394: CDC_2575 | B394: NZ_CP020366.1 | C394: =VLOOKUP($B394,simplified!$B:$F,1,FALSE) -> #N/A | D394: =VLOOKUP($B394,simplified!$B:$F,1,FALSE) -> #N/A | E394: =VLOOKUP($B394,simplified!$B:$F,1,FALSE) -> #N/A | F394: =VLOOKUP($B394,simplified!$B:$F,1,FALSE) -> #N/A | G394: =VLOOKUP($B394,simplified!$B:$F,1,FALSE) -> #N/A | H394: =VLOOKUP($B394,simplified!$B:$F,1,FALSE) -> #N/A
A395: Chicago_Population | B395: NZ_CP010558.1 | C395: =VLOOKUP($B395,simplified!$B:$F,1,FALSE) -> #N/A | D395: =VLOOKUP($B395,simplified!$B:$F,1,FALSE) -> #N/A | E395: =VLOOKUP($B395,simplified!$B:$F,1,FALSE) -> #N/A | F395: =VLOOKUP($B395,simplified!$B:$F,1,FALSE) -> #N/A | G395: =VLOOKUP($B395,simplified!$B:$F,1,FALSE) -> #N/A | H395: =VLOOKUP($B395,simplified!$B:$F,1,FALSE) -> #N/A
A396: Chicago_tube2 | B396: ERR2756161 | C396: =VLOOKUP($B396,simplified!$B:$F,1,FALSE) -> #N/A | D396: =VLOOKUP($B396,simplified!$B:$F,1,FALSE) -> #N/A | E396: =VLOOKUP($B396,simplified!$B:$F,1,FALSE) -> #N/A | F396: =VLOOKUP($B396,simplified!$B:$F,1,FALSE) -> #N/A | G396: =VLOOKUP($B396,simplified!$B:$F,1,FALSE) -> #N/A | H396: =VLOOKUP($B396,simplified!$B:$F,1,FALSE) -> #N/A
A397: CP0461 | B397: ERR1470334 | C397: - | D397: =VLOOKUP($B397,simplified!$B:$F,1,FALSE) -> ERR1470334 | E397: =VLOOKUP($B397,simplified!$B:$F,2,FALSE) -> 0 | F397: =VLOOKUP($B397,simplified!$B:$F,3,FALSE) -> 0 | G397: =VLOOKUP($B397,simplified!$B:$F,4,FALSE) -> 10 | H397: =VLOOKUP($B397,simplified!$B:$F,5,FALSE) -> 0
A398: CP0465 | B398: ERR1470338 | C398: - | D398: =VLOOKUP($B398,simplified!$B:$F,1,FALSE) -> ERR1470338 | E398: =VLOOKUP($B398,simplified!$B:$F,2,FALSE) -> 0 | F398: =VLOOKUP($B398,simplified!$B:$F,3,FALSE) -> 0 | G398: =VLOOKUP($B398,simplified!$B:$F,4,FALSE) -> 10 | H398: =VLOOKUP($B398,simplified!$B:$F,5,FALSE) -> 0
A399: CP0492 | B399: ERR1470344 | C399: - | D399: =VLOOKUP($B399,simplified!$B:$F,1,FALSE) -> ERR1470344 | E399: =VLOOKUP($B399,simplified!$B:$F,2,FALSE) -> 0 | F399: =VLOOKUP($B399,simplified!$B:$F,3,FALSE) -> 0 | G399: =VLOOKUP($B399,simplified!$B:$F,4,FALSE) -> 0 | H399: =VLOOKUP($B399,simplified!$B:$F,5,FALSE) -> 0
A400: CP0495 | B400: ERR1470343 | C400: - | D400: =VLOOKUP($B400,simplified!$B:$F,1,FALSE) -> ERR1470343 | E400: =VLOOKUP($B400,simplified!$B:$F,2,FALSE) -> 0 | F400: =VLOOKUP($B400,simplified!$B:$F,3,FALSE) -> 0 | G400: =VLOOKUP($B400,simplified!$B:$F,4,FALSE) -> 10 | H400: =VLOOKUP($B400,simplified!$B:$F,5,FALSE) -> 0
A401: Cuniculi_A | B401: NC_015714.1 | C401: =VLOOKUP($B401,simplified!$B:$F,1,FALSE) -> #N/A | D401: =VLOOKUP($B401,simplified!$B:$F,1,FALSE) -> #N/A | E401: =VLOOKUP($B401,simplified!$B:$F,1,FALSE) -> #N/A | F401: =VLOOKUP($B401,simplified!$B:$F,1,FALSE) -> #N/A | G401: =VLOOKUP($B401,simplified!$B:$F,1,FALSE) -> #N/A | H401: =VLOOKUP($B401,simplified!$B:$F,1,FALSE) -> #N/A
A402: GHA1 | B402: SRR3268694 | C402: =VLOOKUP($B402,simplified!$B:$F,1,FALSE) -> #N/A | D402: =VLOOKUP($B402,simplified!$B:$F,1,FALSE) -> #N/A | E402: =VLOOKUP($B402,simplified!$B:$F,1,FALSE) -> #N/A | F402: =VLOOKUP($B402,simplified!$B:$F,1,FALSE) -> #N/A | G402: =VLOOKUP($B402,simplified!$B:$F,1,FALSE) -> #N/A | H402: =VLOOKUP($B402,simplified!$B:$F,1,FALSE) -> #N/A
A403: GRA2 | B403: SRR3268696 | C403: =VLOOKUP($B403,simplified!$B:$F,1,FALSE) -> #N/A | D403: =VLOOKUP($B403,simplified!$B:$F,1,FALSE) -> #N/A | E403: =VLOOKUP($B403,simplified!$B:$F,1,FALSE) -> #N/A | F403: =VLOOKUP($B403,simplified!$B:$F,1,FALSE) -> #N/A | G403: =VLOOKUP($B403,simplified!$B:$F,1,FALSE) -> #N/A | H403: =VLOOKUP($B403,simplified!$B:$F,1,FALSE) -> #N/A
A404: IND1_Kampung_Dalan_K363 | B404: SRR3268698 | C404: =VLOOKUP($B404,simplified!$B:$F,1,FALSE) -> #N/A | D404: =VLOOKUP($B404,simplified!$B:$F,1,FALSE) -> #N/A | E404: =VLOOKUP($B404,simplified!$B:$F,1,FALSE) -> #N/A | F404: =VLOOKUP($B404,simplified!$B:$F,1,FALSE) -> #N/A | G404: =VLOOKUP($B404,simplified!$B:$F,1,FALSE) -> #N/A | H404: =VLOOKUP($B404,simplified!$B:$F,1,FALSE) -> #N/A
A405: Kampung_Dalan_K363 | B405: NZ_CP024088.1 | C405: =VLOOKUP($B405,simplified!$B:$F,1,FALSE) -> #N/A | D405: =VLOOKUP($B405,simplified!$B:$F,1,FALSE) -> #N/A | E405: =VLOOKUP($B405,simplified!$B:$F,1,FALSE) -> #N/A | F405: =VLOOKUP($B405,simplified!$B:$F,1,FALSE) -> #N/A | G405: =VLOOKUP($B405,simplified!$B:$F,1,FALSE) -> #N/A | H405: =VLOOKUP($B405,simplified!$B:$F,1,FALSE) -> #N/A
A406: Mexico_A | B406: NC_018722.1 | C406: =VLOOKUP($B406,simplified!$B:$F,1,FALSE) -> #N/A | D406: =VLOOKUP($B406,simplified!$B:$F,1,FALSE) -> #N/A | E406: =VLOOKUP($B406,simplified!$B:$F,1,FALSE) -> #N/A | F406: =VLOOKUP($B406,simplified!$B:$F,1,FALSE) -> #N/A | G406: =VLOOKUP($B406,simplified!$B:$F,1,FALSE) -> #N/A | H406: =VLOOKUP($B406,simplified!$B:$F,1,FALSE) -> #N/A
A407: Nichols_Houston_E | B407: ERR2756162 | C407: =VLOOKUP($B407,simplified!$B:$F,1,FALSE) -> #N/A | D407: =VLOOKUP($B407,simplified!$B:$F,1,FALSE) -> #N/A | E407: =VLOOKUP($B407,simplified!$B:$F,1,FALSE) -> #N/A | F407: =VLOOKUP($B407,simplified!$B:$F,1,FALSE) -> #N/A | G407: =VLOOKUP($B407,simplified!$B:$F,1,FALSE) -> #N/A | H407: =VLOOKUP($B407,simplified!$B:$F,1,FALSE) -> #N/A
A408: Nichols_Houston_J | B408: ERR2756160 | C408: =VLOOKUP($B408,simplified!$B:$F,1,FALSE) -> #N/A | D408: =VLOOKUP($B408,simplified!$B:$F,1,FALSE) -> #N/A | E408: =VLOOKUP($B408,simplified!$B:$F,1,FALSE) -> #N/A | F408: =VLOOKUP($B408,simplified!$B:$F,1,FALSE) -> #N/A | G408: =VLOOKUP($B408,simplified!$B:$F,1,FALSE) -> #N/A | H408: =VLOOKUP($B408,simplified!$B:$F,1,FALSE) -> #N/A
A409: Nichols_Houston_O | B409: ERR2756163 | C409: =VLOOKUP($B409,simplified!$B:$F,1,FALSE) -> #N/A | D409: =VLOOKUP($B409,simplified!$B:$F,1,FALSE) -> #N/A | E409: =VLOOKUP($B409,simplified!$B:$F,1,FALSE) -> #N/A | F409: =VLOOKUP($B409,simplified!$B:$F,1,FALSE) -> #N/A | G409: =VLOOKUP($B409,simplified!$B:$F,1,FALSE) -> #N/A | H409: =VLOOKUP($B409,simplified!$B:$F,1,FALSE) -> #N/A
A410: Nichols_v2 | B410: NC_021490.2 | C410: =VLOOKUP($B410,simplified!$B:$F,1,FALSE) -> #N/A | D410: =VLOOKUP($B410,simplified!$B:$F,1,FALSE) -> #N/A | E410: =VLOOKUP($B410,simplified!$B:$F,1,FALSE) -> #N/A | F410: =VLOOKUP($B410,simplified!$B:$F,1,FALSE) -> #N/A | G410: =VLOOKUP($B410,simplified!$B:$F,1,FALSE) -> #N/A | H410: =VLOOKUP($B410,simplified!$B:$F,1,FALSE) -> #N/A
A411: NKNP-1 | B411: SRR4308606 | C411: - | D411: =VLOOKUP($B411,simplified!$B:$F,1,FALSE) -> SRR4308606 | E411: =VLOOKUP($B411,simplified!$B:$F,2,FALSE) -> 0 | F411: =VLOOKUP($B411,simplified!$B:$F,3,FALSE) -> 0 | G411: =VLOOKUP($B411,simplified!$B:$F,4,FALSE) -> 10 | H411: =VLOOKUP($B411,simplified!$B:$F,5,FALSE) -> 0
A412: NKNP-2 | B412: SRR4308607 | C412: - | D412: =VLOOKUP($B412,simplified!$B:$F,1,FALSE) -> SRR4308607 | E412: =VLOOKUP($B412,simplified!$B:$F,2,FALSE) -> 0 | F412: =VLOOKUP($B412,simplified!$B:$F,3,FALSE) -> 0 | G412: =VLOOKUP($B412,simplified!$B:$F,4,FALSE) -> 10 | H412: =VLOOKUP($B412,simplified!$B:$F,5,FALSE) -> 0
A413: NL09 | B413: ERR2710610 | C413: =VLOOKUP($B413,simplified!$B:$F,1,FALSE) -> #N/A | D413: =VLOOKUP($B413,simplified!$B:$F,1,FALSE) -> #N/A | E413: =VLOOKUP($B413,simplified!$B:$F,1,FALSE) -> #N/A | F413: =VLOOKUP($B413,simplified!$B:$F,1,FALSE) -> #N/A | G413: =VLOOKUP($B413,simplified!$B:$F,1,FALSE) -> #N/A | H413: =VLOOKUP($B413,simplified!$B:$F,1,FALSE) -> #N/A
A414: NL10 | B414: ERR2710611 | C414: =VLOOKUP($B414,simplified!$B:$F,1,FALSE) -> #N/A | D414: =VLOOKUP($B414,simplified!$B:$F,1,FALSE) -> #N/A | E414: =VLOOKUP($B414,simplified!$B:$F,1,FALSE) -> #N/A | F414: =VLOOKUP($B414,simplified!$B:$F,1,FALSE) -> #N/A | G414: =VLOOKUP($B414,simplified!$B:$F,1,FALSE) -> #N/A | H414: =VLOOKUP($B414,simplified!$B:$F,1,FALSE) -> #N/A
...

Sheet ariba
A1: Sample | B1: mlst_report | C1: ST | D1: TP0136 | E1: TP0548 | F1: TP0705
A2: 15169_6#52.Treponema.ds2500000-reads | B2: mlst_report | C2: Novel* | D2: 28* | E2: 14 | F2: 10
A3: 15169_6#53.Treponema.ds2352679-reads | B3: mlst_report | C3: Novel* | D3: 18* | E3: 16* | F3: 10
A4: 15169_6#54.Treponema.ds2500000-reads | B4: mlst_report | C4: Novel* | D4: 28* | E4: 14 | F4: 10
A5: 15169_6#56.Treponema.ds2500000-reads | B5: mlst_report | C5: Novel* | D5: 28* | E5: 14 | F5: 10
A6: 15169_6#60.Treponema.ds2500000-reads | B6: mlst_report | C6: Novel* | D6: 28* | E6: 14 | F6: 10
A7: 15169_6#65.Treponema.ds2500000-reads | B7: mlst_report | C7: Novel* | D7: 28* | E7: 13 | F7: 10
A8: 15169_7#74.Treponema.ds2500000-reads | B8: mlst_report | C8: Novel* | D8: 28* | E8: 15 | F8: 10
A9: 19444_8#14.Treponema.ds2033782-reads | B9: mlst_report | C9: Novel* | D9: 28* | E9: 83* | F9: 10
A10: 19444_8#15.Treponema.ds1410649-reads | B10: mlst_report | C10: Novel* | D10: 28* | E10: 83* | F10: 10
A11: 19444_8#2.Treponema.ds2500000-reads | B11: mlst_report | C11: Novel* | D11: 28* | E11: 83* | F11: 10
A12: 19444_8#6.Treponema.ds996438-reads | B12: mlst_report | C12: Novel* | D12: 28* | E12: 83* | F12: 9*
A13: 19444_8#9.Treponema.ds1440088-reads | B13: mlst_report | C13: Novel* | D13: 28* | E13: 83* | F13: 10
A14: 22931_6#11.Treponema.ds2500000-reads | B14: mlst_report | C14: Novel* | D14: 28* | E14: 1 | F14: 1
A15: 22931_6#12.Treponema.ds778035-reads | B15: mlst_report | C15: Novel* | D15: 28* | E15: 2 | F15: 3
A16: 22931_6#13.Treponema.ds2422288-reads | B16: mlst_report | C16: Novel* | D16: 28* | E16: 2 | F16: 3
A17: 22931_6#4.Treponema.ds2207961-reads | B17: mlst_report | C17: Novel* | D17: 28* | E17: 1 | F17: 1
A18: 22931_6#5.Treponema.ds2500000-reads | B18: mlst_report | C18: Novel* | D18: 28* | E18: 3 | F18: 1
A19: 22931_6#6.Treponema.ds2500000-reads | B19: mlst_report | C19: Novel* | D19: 28* | E19: 3 | F19: 1
A20: 22931_6#7.Treponema.ds726081-reads | B20: mlst_report | C20: 72 | D20: 22 | E20: 3 | F20: 1
A21: 22931_6#8.Treponema.ds1618428-reads | B21: mlst_report | C21: Novel* | D21: 28* | E21: 3 | F21: 1
A22: 22931_6#9.Treponema.ds2500000-reads | B22: mlst_report | C22: Novel* | D22: 28* | E22: 2 | F22: 3
A23: 24141_3#11.Treponema.ds2500000-reads | B23: mlst_report | C23: Novel | D23: 1 | E23: 1 | F23: 2
A24: 24141_3#16.Treponema.ds2500000-reads | B24: mlst_report | C24: 11 | D24: 1 | E24: 1 | F24: 3
A25: 24141_3#17.Treponema.ds2500000-reads | B25: mlst_report | C25: Novel* | D25: 18* | E25: 3 | F25: 1
A26: 24141_4#11.Treponema.ds2500000-reads | B26: mlst_report | C26: Novel* | D26: 1 | E26: 1* | F26: 2
A27: 24141_4#12.Treponema.ds2500000-reads | B27: mlst_report | C27: 11 | D27: 1 | E27: 1 | F27: 3
A28: 24141_4#15.Treponema.ds2500000-reads | B28: mlst_report | C28: 27 | D28: 1 | E28: 1 | F28: 9
A29: 24141_4#18.Treponema.ds2500000-reads | B29: mlst_report | C29: Novel | D29: 1 | E29: 1 | F29: 2
A30: 24141_4#19.Treponema.ds2500000-reads | B30: mlst_report | C30: 27 | D30: 1 | E30: 1 | F30: 9
A31: 24141_4#6.Treponema.ds2500000-reads | B31: mlst_report | C31: 11 | D31: 1 | E31: 1 | F31: 3
A32: 24141_5#11.Treponema.ds2500000-reads | B32: mlst_report | C32: 1 | D32: 1 | E32: 3 | F32: 1
A33: 24141_5#12.Treponema.ds2500000-reads | B33: mlst_report | C33: Novel | D33: 1 | E33: 1 | F33: 2
A34: 24141_5#15.Treponema.ds2500000-reads | B34: mlst_report | C34: 2 | D34: 1 | E34: 1 | F34: 1
A35: 24141_5#16.Treponema.ds2500000-reads | B35: mlst_report | C35: 2 | D35: 1 | E35: 1 | F35: 1
A36: 24141_5#17.Treponema.ds2500000-reads | B36: mlst_report | C36: 11 | D36: 1 | E36: 1 | F36: 3
A37: 24141_5#18.Treponema.ds2471082-reads | B37: mlst_report | C37: Novel | D37: 28 | E37: 7 | F37: 3
A38: 24141_5#20.Treponema.ds2500000-reads | B38: mlst_report | C38: Novel | D38: 1 | E38: 1 | F38: 2
A39: 24141_5#4.Treponema.ds2500000-reads | B39: mlst_report | C39: 27 | D39: 1 | E39: 1 | F39: 9
A40: 24141_5#5.Treponema.ds2500000-reads | B40: mlst_report | C40: 2 | D40: 1 | E40: 1 | F40: 1
...

Sheet blast_assemblies
A1: sample_name | B1: TP0136 | C1: TP0548 | D1: TP0705
A2: 15169_6#52.Treponema.ds2500000-reads | B2: 10 | C2: 14 | D2: 10
A3: 15169_6#53.Treponema.ds2352679-reads | B3: - | C3: - | D3: 10
A4: 15169_6#54.Treponema.ds2500000-reads | B4: 10 | C4: 14 | D4: 10
A5: 15169_6#56.Treponema.ds2500000-reads | B5: 10 | C5: 14 | D5: 10
A6: 15169_6#60.Treponema.ds2500000-reads | B6: 10 | C6: 14 | D6: 10
A7: 15169_6#65.Treponema.ds2500000-reads | B7: 1 | C7: 13 | D7: 10
A8: 15169_7#74.Treponema.ds2500000-reads | B8: 12 | C8: 15 | D8: 10
A9: 19444_8#14.Treponema.ds2033782-reads | B9: - | C9: - | D9: 10
A10: 19444_8#15.Treponema.ds1410649-reads | B10: - | C10: - | D10: 10
A11: 19444_8#2.Treponema.ds2500000-reads | B11: - | C11: - | D11: 10
A12: 19444_8#6.Treponema.ds996438-reads | B12: - | C12: - | D12: 10
A13: 19444_8#9.Treponema.ds1440088-reads | B13: - | C13: - | D13: 10
A14: 22931_6#11.Treponema.ds2500000-reads | B14: 1 | C14: 1 | D14: 1
A15: 22931_6#12.Treponema.ds778035-reads | B15: - | C15: 2 | D15: 3
A16: 22931_6#13.Treponema.ds2422288-reads | B16: 3 | C16: 2 | D16: 3
A17: 22931_6#4.Treponema.ds2207961-reads | B17: 1 | C17: 1 | D17: 1
A18: 22931_6#5.Treponema.ds2500000-reads | B18: 1 | C18: 3 | D18: 1
A19: 22931_6#6.Treponema.ds2500000-reads | B19: 1 | C19: 3 | D19: 1
A20: 22931_6#7.Treponema.ds726081-reads | B20: - | C20: 3 | D20: 1
A21: 22931_6#8.Treponema.ds1618428-reads | B21: 1 | C21: 3 | D21: 1
A22: 22931_6#9.Treponema.ds2500000-reads | B22: 3 | C22: 2 | D22: 3
A23: 24141_3#11.Treponema.ds2500000-reads | B23: 1 | C23: 1 | D23: 2
A24: 24141_3#16.Treponema.ds2500000-reads | B24: 1 | C24: 1 | D24: 3
A25: 24141_3#17.Treponema.ds2500000-reads | B25: 1 | C25: 3 | D25: 1
A26: 24141_4#11.Treponema.ds2500000-reads | B26: 1 | C26: 1 | D26: 2
A27: 24141_4#12.Treponema.ds2500000-reads | B27: 1 | C27: 1 | D27: 3
A28: 24141_4#15.Treponema.ds2500000-reads | B28: 1 | C28: 1 | D28: 9
A29: 24141_4#18.Treponema.ds2500000-reads | B29: 1 | C29: 1 | D29: 2
